2019-11-23 14:42:44,559 ERROR: Exception on /index [GET] [in /Users/amirsciammas/PycharmProjects/microblog/venv/lib/python3.7/site-packages/flask/app.py:1891]
Traceback (most recent call last):
  File "/Users/amirsciammas/PycharmProjects/microblog/venv/lib/python3.7/site-packages/flask/app.py", line 2446, in wsgi_app
    response = self.full_dispatch_request()
  File "/Users/amirsciammas/PycharmProjects/microblog/venv/lib/python3.7/site-packages/flask/app.py", line 1951, in full_dispatch_request
    rv = self.handle_user_exception(e)
  File "/Users/amirsciammas/PycharmProjects/microblog/venv/lib/python3.7/site-packages/flask/app.py", line 1820, in handle_user_exception
    reraise(exc_type, exc_value, tb)
  File "/Users/amirsciammas/PycharmProjects/microblog/venv/lib/python3.7/site-packages/flask/_compat.py", line 39, in reraise
    raise value
  File "/Users/amirsciammas/PycharmProjects/microblog/venv/lib/python3.7/site-packages/flask/app.py", line 1949, in full_dispatch_request
    rv = self.dispatch_request()
  File "/Users/amirsciammas/PycharmProjects/microblog/venv/lib/python3.7/site-packages/flask/app.py", line 1935, in dispatch_request
    return self.view_functions[rule.endpoint](**req.view_args)
  File "/Users/amirsciammas/PycharmProjects/microblog/venv/lib/python3.7/site-packages/flask_login/utils.py", line 261, in decorated_view
    return func(*args, **kwargs)
  File "/Users/amirsciammas/PycharmProjects/microblog/app/routes.py", line 28, in index
    posts=posts)
  File "/Users/amirsciammas/PycharmProjects/microblog/venv/lib/python3.7/site-packages/flask/templating.py", line 140, in render_template
    ctx.app,
  File "/Users/amirsciammas/PycharmProjects/microblog/venv/lib/python3.7/site-packages/flask/templating.py", line 120, in _render
    rv = template.render(context)
  File "/Users/amirsciammas/PycharmProjects/microblog/venv/lib/python3.7/site-packages/jinja2/asyncsupport.py", line 76, in render
    return original_render(self, *args, **kwargs)
  File "/Users/amirsciammas/PycharmProjects/microblog/venv/lib/python3.7/site-packages/jinja2/environment.py", line 1008, in render
    return self.environment.handle_exception(exc_info, True)
  File "/Users/amirsciammas/PycharmProjects/microblog/venv/lib/python3.7/site-packages/jinja2/environment.py", line 780, in handle_exception
    reraise(exc_type, exc_value, tb)
  File "/Users/amirsciammas/PycharmProjects/microblog/venv/lib/python3.7/site-packages/jinja2/_compat.py", line 37, in reraise
    raise value.with_traceback(tb)
  File "/Users/amirsciammas/PycharmProjects/microblog/app/templates/index.html", line 1, in top-level template code
    {% extends "base.html" %}
  File "/Users/amirsciammas/PycharmProjects/microblog/venv/lib/python3.7/site-packages/jinja2/environment.py", line 1005, in render
    return concat(self.root_render_func(self.new_context(vars)))
  File "/Users/amirsciammas/PycharmProjects/microblog/app/templates/index.html", line 14, in root
    <p>{{ submit() }}</p>
  File "/Users/amirsciammas/PycharmProjects/microblog/app/templates/base.html", line 54, in root
  File "/Users/amirsciammas/PycharmProjects/microblog/app/templates/index.html", line 39, in block_content
  File "/Users/amirsciammas/PycharmProjects/microblog/venv/lib/python3.7/site-packages/jinja2/runtime.py", line 262, in call
    return __obj(*args, **kwargs)
  File "/Users/amirsciammas/PycharmProjects/microblog/venv/lib/python3.7/site-packages/jinja2/runtime.py", line 630, in _fail_with_undefined_error
    raise self._undefined_exception(hint)
jinja2.exceptions.UndefinedError: 'submit' is undefined
2019-11-23 14:43:11,267 INFO: Microblog startup [in /Users/amirsciammas/PycharmProjects/microblog/app/__init__.py:46]
2019-11-23 14:50:40,152 INFO: Microblog startup [in /Users/amirsciammas/PycharmProjects/microblog/app/__init__.py:46]
